<?xml version="1.0" encoding="utf-8"?>
<!-- =================================================================================== -->
<!-- |    This document was autogenerated by xacro from niryo_ned2_robot.urdf.xacro    | -->
<!-- |    EDITING THIS FILE BY HAND IS NOT RECOMMENDED                                 | -->
<!-- =================================================================================== -->
<robot name="niryo_ned2">
  <transmission name="transmission_1">
    <type>transmission_interface/SimpleTransmission</type>
    <joint name="joint_1">
      <hardwareInterface>hardware_interface/PositionJointInterface</hardwareInterface>
    </joint>
    <actuator name="motor_1">
      <mechanicalReduction>1</mechanicalReduction>
    </actuator>
  </transmission>
  <transmission name="transmission_2">
    <type>transmission_interface/SimpleTransmission</type>
    <joint name="joint_2">
      <hardwareInterface>hardware_interface/PositionJointInterface</hardwareInterface>
    </joint>
    <actuator name="motor_2">
      <mechanicalReduction>1</mechanicalReduction>
    </actuator>
  </transmission>
  <transmission name="transmission_3">
    <type>transmission_interface/SimpleTransmission</type>
    <joint name="joint_3">
      <hardwareInterface>hardware_interface/PositionJointInterface</hardwareInterface>
    </joint>
    <actuator name="motor_3">
      <mechanicalReduction>1</mechanicalReduction>
    </actuator>
  </transmission>
  <transmission name="transmission_4">
    <type>transmission_interface/SimpleTransmission</type>
    <joint name="joint_4">
      <hardwareInterface>hardware_interface/PositionJointInterface</hardwareInterface>
    </joint>
    <actuator name="motor_4">
      <mechanicalReduction>1</mechanicalReduction>
    </actuator>
  </transmission>
  <transmission name="transmission_5">
    <type>transmission_interface/SimpleTransmission</type>
    <joint name="joint_5">
      <hardwareInterface>hardware_interface/PositionJointInterface</hardwareInterface>
    </joint>
    <actuator name="motor_5">
      <mechanicalReduction>1</mechanicalReduction>
    </actuator>
  </transmission>
  <transmission name="transmission_6">
    <type>transmission_interface/SimpleTransmission</type>
    <joint name="joint_6">
      <hardwareInterface>hardware_interface/PositionJointInterface</hardwareInterface>
    </joint>
    <actuator name="motor_6">
      <mechanicalReduction>1</mechanicalReduction>
    </actuator>
  </transmission>
  <transmission name="transmission_7">
    <type>transmission_interface/SimpleTransmission</type>
    <joint name="joint_base_to_mors_1">
      <hardwareInterface>hardware_interface/EffortJointInterface</hardwareInterface>
    </joint>
    <actuator name="motor_7">
      <mechanicalReduction>1</mechanicalReduction>
    </actuator>
  </transmission>
  <transmission name="transmission_8">
    <type>transmission_interface/SimpleTransmission</type>
    <joint name="joint_base_to_mors_2">
      <hardwareInterface>hardware_interface/EffortJointInterface</hardwareInterface>
    </joint>
    <actuator name="motor_8">
      <mechanicalReduction>1</mechanicalReduction>
    </actuator>
  </transmission>
  <link name="bakje_1">
    <inertial>
      <origin rpy="0 0 0" xyz="0 0 0"/>
      <mass value="0.01"/>
      <inertia ixx="0.00055187" ixy="0.0" ixz="0.0" iyy="0.00073447" iyz="0.0" izz="0.00049414"/>
    </inertial>
    <collision>
      <origin rpy="0 0 0" xyz="0 0 0"/>
      <geometry>
        <mesh filename="package://my_niryo_robot_description/meshes/bakje_colision.stl"/>
      </geometry>
    </collision>
    <visual>
      <origin rpy="0.0 0 0" xyz="0 0 0"/>
      <geometry>
        <mesh filename="package://my_niryo_robot_description/meshes/bakje.dae"/>
      </geometry>
    </visual>
  </link>
  <gazebo reference="bakje_1">
    <mu1>10.0</mu1>
    <mu2>10.0</mu2>
  </gazebo>
  <joint name="bakje_1_joint" type="fixed">
    <parent link="baseplate_link"/>
    <child link="bakje_1"/>
    <origin rpy="0.0 0.0 1.57079632679" xyz="-0.4 -0.3 0.015"/>
  </joint>
  <link name="bakje_2">
    <inertial>
      <origin rpy="0 0 0" xyz="0 0 0"/>
      <mass value="0.01"/>
      <inertia ixx="0.00055187" ixy="0.0" ixz="0.0" iyy="0.00073447" iyz="0.0" izz="0.00049414"/>
    </inertial>
    <collision>
      <origin rpy="0 0 0" xyz="0 0 0"/>
      <geometry>
        <mesh filename="package://my_niryo_robot_description/meshes/bakje_colision.stl"/>
      </geometry>
    </collision>
    <visual>
      <origin rpy="0.0 0 0" xyz="0 0 0"/>
      <geometry>
        <mesh filename="package://my_niryo_robot_description/meshes/bakje.dae"/>
      </geometry>
    </visual>
  </link>
  <gazebo reference="bakje_2">
    <mu1>10.0</mu1>
    <mu2>10.0</mu2>
  </gazebo>
  <joint name="bakje_2_joint" type="fixed">
    <parent link="baseplate_link"/>
    <child link="bakje_2"/>
    <origin rpy="0.0 0.0 1.57079632679" xyz="-0.4 -0.15 0.015"/>
  </joint>
  <link name="bakje_3">
    <inertial>
      <origin rpy="0 0 0" xyz="0 0 0"/>
      <mass value="0.01"/>
      <inertia ixx="0.00055187" ixy="0.0" ixz="0.0" iyy="0.00073447" iyz="0.0" izz="0.00049414"/>
    </inertial>
    <collision>
      <origin rpy="0 0 0" xyz="0 0 0"/>
      <geometry>
        <mesh filename="package://my_niryo_robot_description/meshes/bakje_colision.stl"/>
      </geometry>
    </collision>
    <visual>
      <origin rpy="0.0 0 0" xyz="0 0 0"/>
      <geometry>
        <mesh filename="package://my_niryo_robot_description/meshes/bakje.dae"/>
      </geometry>
    </visual>
  </link>
  <gazebo reference="bakje_3">
    <mu1>10.0</mu1>
    <mu2>10.0</mu2>
  </gazebo>
  <joint name="bakje_3_joint" type="fixed">
    <parent link="baseplate_link"/>
    <child link="bakje_3"/>
    <origin rpy="0.0 0.0 1.57079632679" xyz="-0.4 0 0.015"/>
  </joint>
  <link name="bakje_4">
    <inertial>
      <origin rpy="0 0 0" xyz="0 0 0"/>
      <mass value="0.01"/>
      <inertia ixx="0.00055187" ixy="0.0" ixz="0.0" iyy="0.00073447" iyz="0.0" izz="0.00049414"/>
    </inertial>
    <collision>
      <origin rpy="0 0 0" xyz="0 0 0"/>
      <geometry>
        <mesh filename="package://my_niryo_robot_description/meshes/bakje_colision.stl"/>
      </geometry>
    </collision>
    <visual>
      <origin rpy="0.0 0 0" xyz="0 0 0"/>
      <geometry>
        <mesh filename="package://my_niryo_robot_description/meshes/bakje.dae"/>
      </geometry>
    </visual>
  </link>
  <gazebo reference="bakje_4">
    <mu1>10.0</mu1>
    <mu2>10.0</mu2>
  </gazebo>
  <joint name="bakje_4_joint" type="fixed">
    <parent link="baseplate_link"/>
    <child link="bakje_4"/>
    <origin rpy="0.0 0.0 1.57079632679" xyz="-0.4 0.15 0.015"/>
  </joint>
  <link name="camera_holder">
    <inertial>
      <origin rpy="0 0 0" xyz="0.0 0.0 0.0"/>
      <mass value="0.01"/>
      <inertia ixx="0.00000147" ixy="0.0" ixz="0.0" iyy="0.00000282" iyz="0.0" izz="0.00000387"/>
    </inertial>
    <visual>
      <origin rpy="0 0 0" xyz="0 0 0"/>
      <geometry>
        <mesh filename="package://my_niryo_robot_description/meshes/cameraHouder.dae"/>
      </geometry>
      <material name="">
        <color rgba="0.49804 0.49804 0.49804 1"/>
      </material>
    </visual>
    <collision>
      <origin rpy="0 0 0" xyz="0 0 0"/>
      <geometry>
        <mesh filename="package://my_niryo_robot_description/meshes/cameraHouder_colision.stl"/>
      </geometry>
    </collision>
  </link>
  <link name="camera">
    <inertial>
      <origin rpy="0 0 0" xyz="0.0 0.0 0.0"/>
      <mass value="0.01"/>
      <inertia ixx="0.00000147" ixy="0.0" ixz="0.0" iyy="0.00000282" iyz="0.0" izz="0.00000387"/>
    </inertial>
    <visual>
      <origin rpy="0 0 0" xyz="0 0 0"/>
      <geometry>
        <mesh filename="package://my_niryo_robot_description/meshes/OAK-D.stl"/>
      </geometry>
      <material name="">
        <color rgba="0.49804 0.49804 0.49804 1"/>
      </material>
    </visual>
    <collision>
      <origin rpy="0 0 0" xyz="0 0 0"/>
      <geometry>
        <mesh filename="package://my_niryo_robot_description/meshes/OAK-D.stl"/>
      </geometry>
    </collision>
  </link>
  <!-- Joint from tool_link to base_gripper -->
  <joint name="wrist_to_camera_holder" type="fixed">
    <parent link="wrist_link"/>
    <child link="camera_holder"/>
    <origin rpy="1.57079632679 -1.57079632679 0" xyz="0 0.017 0"/>
  </joint>
  <joint name="holder_to_camera" type="fixed">
    <parent link="camera_holder"/>
    <child link="camera"/>
    <origin rpy="1.57079632679 0 0" xyz="0 -0.0355 -0.025"/>
  </joint>
  <!-- material -->
  <gazebo reference="camera_holder">
    <material>Gazebo/DarkGrey</material>
  </gazebo>
  <!-- Base Gripper -->
  <link name="base_gripper_1">
    <inertial>
      <origin rpy="0 0 0" xyz="0 0 0"/>
      <mass value="0.01"/>
      <inertia ixx="0.00862940" ixy="0.0" ixz="0.0" iyy="0.02072169" iyz="0.0" izz="0.02327580"/>
    </inertial>
    <visual>
      <origin rpy="0 0 0" xyz="0 0 0"/>
      <geometry>
        <mesh filename="package://my_niryo_robot_description/meshes/gripper_base.dae"/>
      </geometry>
    </visual>
    <collision>
      <origin rpy="0 0 0" xyz="0 0 0"/>
      <geometry>
        <mesh filename="package://my_niryo_robot_description/meshes/grippe_base_colision.stl"/>
      </geometry>
    </collision>
  </link>
  <!-- Joint from tool_link to base_gripper -->
  <joint name="joint_to_gripper" type="fixed">
    <parent link="tool_link"/>
    <child link="base_gripper_1"/>
    <origin rpy="0 3.14159265359 -1.57079632679" xyz="-0.016 0 0"/>
  </joint>
  <!-- klep 1 -->
  <link name="mors_1">
    <inertial>
      <origin rpy="0 0 0" xyz="0 0 0"/>
      <mass value="0.01335241"/>
      <inertia ixx="0.00000297" ixy="0.00000068" ixz="0.00000002" iyy="0.00000099" iyz="0.00000010" izz="0.00000282"/>
    </inertial>
    <visual>
      <origin rpy="0 0 0" xyz="0 0 0"/>
      <geometry>
        <mesh filename="package://my_niryo_robot_description/meshes/gripper_left.dae"/>
      </geometry>
      <material name="">
        <color rgba="0.49804 0.49804 0.49804 1"/>
      </material>
    </visual>
    <collision>
      <origin rpy="0 0 0" xyz="0 0 0"/>
      <geometry>
        <mesh filename="package://my_niryo_robot_description/meshes/grippe_left_colision.stl"/>
      </geometry>
    </collision>
  </link>
  <joint name="joint_base_to_mors_1" type="fixed">
    <origin rpy="0 0 0" xyz="-0.0265 0.0425 -0.008"/>
    <parent link="base_gripper_1"/>
    <child link="mors_1"/>
    <!-- <axis xyz="1 0 0"/>
        <limit lower="0"
               upper="0.01"
               effort="1"
               velocity="5"/> -->
  </joint>
  <!-- klep 2 -->
  <link name="mors_2">
    <inertial>
      <origin rpy="0 0 0" xyz="0 0 0"/>
      <mass value="0.01335241"/>
      <inertia ixx="0.00000297" ixy="0.00000068" ixz="0.00000002" iyy="0.00000099" iyz="0.00000010" izz="0.00000282"/>
    </inertial>
    <visual>
      <origin rpy="0 0 0" xyz="0 0 0"/>
      <geometry>
        <mesh filename="package://my_niryo_robot_description/meshes/gripper_right.dae"/>
      </geometry>
      <material name="">
        <color rgba="0.49804 0.49804 0.49804 1"/>
      </material>
    </visual>
    <collision>
      <origin rpy="0 0 0" xyz="0 0 0"/>
      <geometry>
        <mesh filename="package://my_niryo_robot_description/meshes/grippe_right_colision.stl"/>
      </geometry>
    </collision>
  </link>
  <joint name="joint_base_to_mors_2" type="fixed">
    <origin rpy="0 0 0" xyz="0.0255 0.044 -0.008"/>
    <parent link="base_gripper_1"/>
    <child link="mors_2"/>
    <!-- <axis xyz="1 0 0"/>
        <limit lower="-0.01"
               upper="0"
               effort="1"
               velocity="5"/> -->
  </joint>
  <!-- material -->
  <gazebo reference="base_gripper_1">
    <material>Gazebo/DarkGrey</material>
  </gazebo>
  <gazebo reference="mors_1">
    <material>Gazebo/DarkGrey</material>
  </gazebo>
  <gazebo reference="mors_2">
    <material>Gazebo/DarkGrey</material>
  </gazebo>
  <link name="schot">
    <inertial>
      <origin rpy="0 0 0" xyz="0 0 0"/>
      <mass value="0.01"/>
      <inertia ixx="7.58333333333e-05" ixy="0.0" ixz="0.0" iyy="0.00015000000000000001" iyz="0.0" izz="7.50208333333"/>
    </inertial>
    <collision>
      <origin rpy="0 0 0" xyz="0 0 0"/>
      <geometry>
        <mesh filename="package://my_niryo_robot_description/meshes/schot_colision.stl"/>
      </geometry>
    </collision>
    <visual>
      <origin rpy="0.0 0 0" xyz="0 0 0"/>
      <geometry>
        <mesh filename="package://my_niryo_robot_description/meshes/schotv2.dae"/>
      </geometry>
    </visual>
  </link>
  <gazebo reference="schot">
    <mu1>10.0</mu1>
    <mu2>10.0</mu2>
  </gazebo>
  <joint name="fixed" type="fixed">
    <parent link="baseplate_link"/>
    <child link="schot"/>
    <origin rpy="0 0 1.57079632679" xyz="0.1 -0.14 0.015"/>
  </joint>
  <!-- Properties -->
  <!-- Links -->
  <!--
    <link name="world"/>
-->
  <link name="base_link">
    <inertial>
      <origin rpy="0 0 0" xyz="-0.008924 0.0001357 0.052392"/>
      <mass value="0.71142"/>
      <inertia ixx="0.0017" ixy="0.0" ixz="0.0" iyy="0.0017" iyz="0.0" izz="0.0032"/>
    </inertial>
    <visual>
      <origin rpy="0 0 0" xyz="0 0 0"/>
      <geometry>
        <mesh filename="package://niryo_robot_description/meshes/ned2/collada/base_link.dae"/>
      </geometry>
    </visual>
    <collision>
      <origin rpy="-1.5707963268 0 0" xyz="0 0 0"/>
      <geometry>
        <mesh filename="package://niryo_robot_description/meshes/ned2/stl/base_link.stl"/>
      </geometry>
    </collision>
  </link>
  <link name="led_ring_link">
    <!--
        <visual>
            <origin xyz="0 0 0"
                    rpy="0 0 0"/>
            <geometry>
                <cylinder length="0.0019" radius="0.0775"/>
            </geometry>
            <material
                    name="">
                <color
                        rgba="1 1 1 0.25"/>
            </material>
        </visual> -->
  </link>
  <link name="shoulder_link">
    <inertial>
      <origin rpy="0 0 0" xyz="-0.031951 0.0080419 0.030675"/>
      <mass value="0.35056"/>
      <inertia ixx="0.00023875" ixy="2.3853E-08" ixz="2.0596E-06" iyy="0.00032638" iyz="-8.9319E-07" izz="0.00030089"/>
    </inertial>
    <visual>
      <origin rpy="0 0 0" xyz="0 0 0"/>
      <geometry>
        <mesh filename="package://niryo_robot_description/meshes/ned2/collada/shoulder_link.dae"/>
      </geometry>
    </visual>
    <collision>
      <origin rpy="0 0 0" xyz="0 0 0"/>
      <geometry>
        <mesh filename="package://niryo_robot_description/meshes/ned2/stl/shoulder_link.stl"/>
      </geometry>
    </collision>
  </link>
  <link name="arm_link">
    <inertial>
      <origin rpy="0 3.14159265359 0" xyz="-0.00096976 0.086432 0.0038832"/>
      <mass value="1.0838"/>
      <inertia ixx="0.008194" ixy="0.00015602" ixz="-3.434E-06" iyy="0.0011945" iyz="-0.00031298" izz="0.007915"/>
    </inertial>
    <visual>
      <origin rpy="0 3.14159265359 0" xyz="0 0 0"/>
      <geometry>
        <mesh filename="package://niryo_robot_description/meshes/ned2/collada/arm_link.dae"/>
      </geometry>
    </visual>
    <collision>
      <origin rpy="0 3.14159265359 0" xyz="0 0 0"/>
      <geometry>
        <mesh filename="package://niryo_robot_description/meshes/ned2/stl/arm_link.stl"/>
      </geometry>
    </collision>
  </link>
  <link name="elbow_link">
    <inertial>
      <origin rpy="0 3.14159265359 0" xyz="-0.019703 0.037336 -1.7431E-09"/>
      <mass value="0.22126"/>
      <inertia ixx="0.00011754" ixy="-1.2314E-05" ixz="-6.2064E-11" iyy="0.00020851" iyz="9.2393E-11" izz="0.00022753"/>
    </inertial>
    <visual>
      <origin rpy="0 3.14159265359 0" xyz="0 0 0"/>
      <geometry>
        <mesh filename="package://niryo_robot_description/meshes/ned2/collada/elbow_link.dae"/>
      </geometry>
    </visual>
    <collision>
      <origin rpy="0 3.14159265359 0" xyz="0 0 0"/>
      <geometry>
        <mesh filename="package://niryo_robot_description/meshes/ned2/stl/elbow_link.stl"/>
      </geometry>
    </collision>
  </link>
  <link name="forearm_link">
    <inertial>
      <origin rpy="0 0 0" xyz="-0.0049532 7.8351E-06 0.08106"/>
      <mass value="0.35686"/>
      <inertia ixx="0.0013664" ixy="-9.6367E-08" ixz="0.00013594" iyy="0.0014781" iyz="-1.4596E-07" izz="0.00023715"/>
    </inertial>
    <visual>
      <origin rpy="0 0 0" xyz="0 0 0"/>
      <geometry>
        <mesh filename="package://niryo_robot_description/meshes/ned2/collada/forearm_link.dae"/>
      </geometry>
    </visual>
    <collision>
      <origin rpy="0 0 0" xyz="0 0 0"/>
      <geometry>
        <mesh filename="package://niryo_robot_description/meshes/ned2/stl/forearm_link.stl"/>
      </geometry>
    </collision>
  </link>
  <!-- add collision for the motor of joint 5 -->
  <!-- <link name="joint5_motor">
        <inertial>
            <origin xyz="0 0 0.015" rpy="0 0 0"/>
            <mass value="0.203543862275952"/>
            <inertia ixx="0.0015" ixy="0.0" ixz="0.0" iyy="0.0015" iyz="0.0" izz="0.0015"/>
        </inertial>
        <collision>
            <origin xyz="0 0 0.015" rpy="0 0 0"/>
            <geometry>
                <box size="0.047 0.0285 0.03"/>
            </geometry>
        </collision>
    </link> -->
  <link name="wrist_link">
    <inertial>
      <origin rpy="0 0 0" xyz="-0.019666 0.037312 0.0"/>
      <mass value="0.22126"/>
      <inertia ixx="0.0015" ixy="0.0" ixz="0.0" iyy="0.0015" iyz="0.0" izz="0.0015"/>
    </inertial>
    <visual>
      <origin rpy="0 0 0" xyz="0 0 0"/>
      <geometry>
        <mesh filename="package://niryo_robot_description/meshes/ned2/collada/wrist_link.dae"/>
      </geometry>
    </visual>
    <collision>
      <origin rpy="0 0 0" xyz="0 0 0"/>
      <geometry>
        <mesh filename="package://niryo_robot_description/meshes/ned2/stl/wrist_link.stl"/>
      </geometry>
    </collision>
  </link>
  <link name="hand_link">
    <inertial>
      <origin rpy="0 0 0" xyz="0 0 0.009"/>
      <mass value="0.0070027"/>
      <inertia ixx="0.0015" ixy="0.0" ixz="0.0" iyy="0.0015" iyz="0.0" izz="0.0015"/>
    </inertial>
    <visual>
      <origin rpy="0 0 0" xyz="0 0 0"/>
      <geometry>
        <mesh filename="package://niryo_robot_description/meshes/ned2/collada/hand_link.dae"/>
      </geometry>
    </visual>
    <collision>
      <origin rpy="0 0 0" xyz="0 0 0"/>
      <geometry>
        <mesh filename="package://niryo_robot_description/meshes/ned2/stl/hand_link.stl"/>
      </geometry>
    </collision>
  </link>
  <link name="tool_link">
    </link>
  <!-- Joints -->
  <!--
    <joint name="joint_world" type="fixed">
        <parent link="world"/>
        <child link="base_link"/>
        <origin xyz="0 0 0" rpy="0 0 0"/>
    </joint>
-->
  <joint name="joint_1" type="revolute">
    <origin rpy="0 0 -1.5707963268" xyz="0 0 0.1013"/>
    <parent link="base_link"/>
    <child link="shoulder_link"/>
    <axis xyz="0 0 1"/>
    <limit effort="10.0" lower="-2.99987191833" upper="2.99987191833" velocity="10.0"/>
  </joint>
  <joint name="joint_2" type="revolute">
    <origin rpy="1.5707963268 0 1.5707963268" xyz="0 0 0.065"/>
    <parent link="shoulder_link"/>
    <child link="arm_link"/>
    <axis xyz="0 0 1"/>
    <limit effort="10.0" lower="-1.83259571459" upper="0.610167106497" velocity="8.0"/>
  </joint>
  <joint name="joint_3" type="revolute">
    <origin rpy="0 0 0" xyz="0.012 0.221 0"/>
    <parent link="arm_link"/>
    <child link="elbow_link"/>
    <axis xyz="0 0 1"/>
    <limit effort="7.0" lower="-1.34006379968" upper="1.57009819509" velocity="8.0"/>
  </joint>
  <joint name="joint_4" type="revolute">
    <origin rpy="0 1.5707963268 0" xyz="0.065 0.0325 0"/>
    <parent link="elbow_link"/>
    <child link="forearm_link"/>
    <axis xyz="0 0 1"/>
    <limit effort="7.0" lower="-2.09003177926" upper="2.09003177926" velocity="2.0"/>
  </joint>
  <joint name="joint_5" type="revolute">
    <origin rpy="3.14159265359 -1.5707963268 3.14159265359" xyz="0 0 0.17"/>
    <parent link="forearm_link"/>
    <child link="wrist_link"/>
    <axis xyz="0 0 1"/>
    <limit effort="6.0" lower="-1.92003671012" upper="1.92282923692" velocity="2.0"/>
  </joint>
  <joint name="joint_6" type="revolute">
    <origin rpy="0 1.5707963268 0" xyz="0.0197 0.00925 0"/>
    <parent link="wrist_link"/>
    <child link="hand_link"/>
    <axis xyz="0 0 1"/>
    <limit effort="5.0" lower="-2.53002928369" upper="2.53002928369" velocity="2.0"/>
  </joint>
  <joint name="hand_tool_joint" type="fixed">
    <parent link="hand_link"/>
    <child link="tool_link"/>
    <origin rpy="-1.5707963268 -1.5707963268 0" xyz="0 0 0.0285"/>
  </joint>
  <!-- <joint name="joint_test" type="fixed">
        <origin xyz="-0.03 0 0.158" rpy="0 -${PI/2} 0"/>
        <parent link="forearm_link"/>
        <child link="joint5_motor"/>
    </joint> -->
  <joint name="joint_led_ring" type="fixed">
    <parent link="world"/>
    <child link="led_ring_link"/>
    <origin rpy="0 0 0" xyz="0 0 0.0923"/>
  </joint>
  <material name="LightGrey">
    <color rgba="0.7 0.7 0.7 1.0"/>
  </material>
  <material name="blue">
    <color rgba="0 0 0.8 1"/>
  </material>
  <material name="red">
    <color rgba="0.8 0 0 1"/>
  </material>
  <link name="world"/>
  <link name="baseplate_link">
    <visual>
      <origin xyz="0 0 0.0"/>
      <geometry>
        <box size="1.1 0.7 0.03"/>
      </geometry>
      <material name="LightGrey"/>
    </visual>
    <inertial>
      <mass value="10"/>
      <inertia ixx="0.409083333333" ixy="0" ixz="0" iyy="1.00908333333" iyz="0" izz="1.00908333333"/>
    </inertial>
  </link>
  <joint name="baseplate_joint" type="fixed">
    <origin rpy="0.0 0.0 1.57079632679" xyz="0.20 0 0"/>
    <parent link="world"/>
    <child link="baseplate_link"/>
  </joint>
  
world

  
  <!-- robot to baseplate_joint. -->
  <joint name="mountingplate_link" type="fixed">
    <parent link="world"/>
    <child link="base_link"/>
    <origin rpy="0.0 0.0 0" xyz="0.0 0.0 0.021"/>
  </joint>
  <!-- Joint from tool_link to base_gripper -->
  <!--

  <xacro:include filename="$(find my_niryo_robot_description)/urdf/ned/niryo_ned_gripper.urdf.xacro"/>
  <xacro:niryo_ned_gripper/>

    <joint name="joint_to_gripper" type="fixed">
        <parent link="tool_link"/>
        <child link="base_gripper_1"/>
        <origin
                xyz="0 0 0.005"
                rpy="0 ${pi/2} ${pi/2}"/>
    </joint>
  -->
  <!-- tool center point -->
  <link name="tcp_link"/>
  <joint name="tool0_link" type="fixed">
    <parent link="tool_link"/>
    <child link="tcp_link"/>
    <origin rpy="0.0 0.0 0.0" xyz="0.0 0.0 0.0"/>
  </joint>
</robot>

